Workbook

Sheet Start Here
B2: AI Engineer Roadmap 2027: Tracker
B3: AI Anytime · Edition 1.0 · September 2026 · Licensed for personal use
B5: How to use this workbook
B6: 1. Open the Dashboard tab and fill the yellow cells: your name, track, start date (first day of Month 1), weekly hours, target role and city.
B7: 2. Roadmap: planned dates calculate from your start date. Change Status as you finish each month (only after its assessment).
B8: 3. Skills Matrix: update Current level (0-5) and Evidence link at every monthly review. 'Demonstrated' needs a link someone else can check.
B9: 4. Learning Tracker lists every resource the roadmap assigns, month by month. Log hours and the artifact each resource produced.
B10: 5. Projects, Capstone and GitHub tabs are your portfolio command centre.
B11: 6. Question Bank: rate confidence 1-3 after practising; Next review is calculated (1 = 3 days, 2 = 7 days, 3 = 14 days).
B12: 7. Mock Interviews, Job Research, Target Companies, Applications and Networking run your job search. The Dashboard shows funnel conversion.
B13: 8. Weekly Review every Sunday (20 minutes). Monthly Review on the last Sunday of each month (60 minutes).
B15: Yellow cells are for your input. Black header rows are fixed. Filters are enabled on every tab.
... B24: 0 Awareness: can explain · 1 Guided: can follow a tutorial · 2 Independent: builds without copying · 3 Production: deploys and operates · 4 Advanced: designs and debugs · 5 Expert: makes trade-offs, teaches, innovates

Sheet Dashboard
B2: Dashboard
B3: Fill the yellow cells. Everything else updates automatically.
B5: Name
B6: Track | C6: 1. Beginner → AI Engineer
B7: Start date (Month 1)
B8: Weekly hours | C8: 15
B9: Target role | C9: AI Engineer
B10: Target city | C10: Hyderabad
B12: PROGRESS | E12: INTERVIEWS
B13: Roadmap months completed | C13: =COUNTIF(Roadmap!K:K,"Done")&" / 13" | E13: Questions practised | F13: =COUNTA('Question Bank'!J2:J301)&" / 300"
B14: Current month (by date) | C14: =IF(C7="","set start date",IFERROR(MAX(0,MIN(12,DATEDIF(C7,TODAY(),"m")+1)),"not started yet")) | E14: Average confidence (1-3) | F14: =IFERROR(ROUND(AVERAGE('Question Bank'!I2:I301),2),"-")
B15: Hours logged (Weekly Review) | C15: =SUM('Weekly Review'!G:G) | E15: Questions due for review | F15: =COUNTIFS('Question Bank'!K2:K301,"<="&TODAY(),'Question Bank'!K2:K301,"<>")
B16: Hours logged (Learning Tracker) | C16: =SUM('Learning Tracker'!F:F) | E16: Mock interview average (1-4) | F16: =IFERROR(ROUND(AVERAGE('Mock Interviews'!N:N),2),"-")
B17: SKILLS | E17: JOB SEARCH
B18: Skills demonstrated | C18: =COUNTIF('Skills Matrix'!G:G,"Demonstrated")&" / 52" | E18: Applications sent | F18: =COUNTA(Applications!B2:B1000)
B19: Skills at or above target | C19: =SUMPRODUCT(('Skills Matrix'!F2:F53<>"")*('Skills Matrix'!F2:F53>='Skills Matrix'!E2:E53))&" / 52" | E19: With referral | F19: =COUNTIF(Applications!F:F,"Yes")
B20: Skills interview ready | C20: =COUNTIF('Skills Matrix'!J:J,"Yes")&" / 52" | E20: Reached screen or later | F20: =COUNTIF(Applications!G:G,"Screen")+COUNTIF(Applications!G:G,"Technical")+COUNTIF(Applications!G:G,"Final")+COUNTIF(Applications!G:G,"Offer")
B21: PORTFOLIO | E21: Reached final round or offer | F21: =COUNTIF(Applications!G:G,"Final")+COUNTIF(Applications!G:G,"Offer")
B22: Projects done | C22: =COUNTIF(Projects!L:L,"Done")&" / 7" | E22: Offers | F22: =COUNTIF(Applications!G:G,"Offer")
B23: Projects interview ready | C23: =COUNTIF(Projects!M:M,"Yes")&" / 7" | E23: Application → screen rate | F23: =IFERROR(TEXT(F20/F18,"0%"),"-")
B24: Capstone rubric score | C24: =Capstone!C40&" / 60" | E24: Networking contacts | F24: =COUNTA(Networking!A2:A1000)

Sheet Roadmap
A1: Month | B1: Theme | C1: Planned start | D1: Planned end | E1: Milestone | F1: Goal | G1: Build | H1: Artifact | I1: Assessment | J1: Hours | K1: Status | L1: Completed on | M1: Rubric avg (1-4) | N1: Notes
A2: 0 | B2: On-ramp: from zero to writing Python | C2: =IF(Dashboard!$C$7="","",EDATE(Dashboard!$C$7,A2-1)) | D2: =IF(C2="","",EDATE(C2,1)-1) | E2: Only for non-tech learners and students who cannot code yet (6-8 weeks) | F2: Write small Python programs without copying, use the terminal and push code to GitHub. | G2: 3 small programs: expense tracker (CSV), quiz game, file organizer | H2: GitHub profile with 3 repos, each with a short README | I2: Solve 5 unseen beginner problems in 90 minutes without AI help. Pass = 4/5 working. | J2: 60-90 | K2: Not started
A3: 1 | B3: Engineering foundations and your first AI app | C3: =IF(Dashboard!$C$7="","",EDATE(Dashboard!$C$7,A3-1)) | D3: =IF(C3="","",EDATE(C3,1)-1) | E3: 30-day milestone: foundation + first working AI application | F3: Set up a professional dev environment and ship a working command-line AI tool that calls an LLM API. | G3: AI CLI tool: summarizes a folder of text/PDF files into structured notes (title, key points, action items) saved as JSON and Markdown | H3: Repo 'ai-notes-cli' with README, usage GIF, .env.example, basic tests | I3: Rebuild the CLI core from an empty folder in 2 hours with docs only. Explain every line in a 5-minute recording. | J3: 60 | K3: Not started
A4: 2 | B4: LLM engineering core | C4: =IF(Dashboard!$C$7="","",EDATE(Dashboard!$C$7,A4-1)) | D4: =IF(C4="","",EDATE(C4,1)-1) | E4: Project 1 shipped | F4: Build a production-style AI API that handles structured output, tool calling, model comparison, cost and latency tracking. | G4: Project 1: Production-style AI API (model comparison service) | H4: Dockerized API + benchmark table + architecture diagram + README | I4: Project 1 acceptance criteria met (see project ladder). Level 2 on S03, S18, S19, S20. | J4: 60 | K4: Not started
A5: 3 | B5: How LLMs actually work | C5: =IF(Dashboard!$C$7="","",EDATE(Dashboard!$C$7,A5-1)) | D5: =IF(C5="","",EDATE(C5,1)-1) | E5: Foundations that interviews test | F5: Understand neural networks, transformers and embeddings well enough to explain and debug model behaviour. | G5: Mini GPT notebook + 'embedding explorer' app that finds similar sentences in your own notes | H5: Notebook repo with explanations in your own words; small embedding search demo | I5: Whiteboard attention and a transformer block in 10 minutes. Reproduce P01 exercise. Level 2 on S13, S14, S15. | J5: 60-70 | K5: Not started
A6: 4 | B6: Retrieval-augmented generation | C6: =IF(Dashboard!$C$7="","",EDATE(Dashboard!$C$7,A6-1)) | D6: =IF(C6="","",EDATE(C6,1)-1) | E6: Project 2 shipped | F6: Build and evaluate a RAG system that answers from documents with citations and measured quality. | G6: Project 2: Evaluated RAG application | H6: Deployed RAG app + evaluation report + experiment log + architecture diagram | I6: Recall@5 and faithfulness reported on 100 questions; explain two failure cases and fixes. Level 3 on S23-S26. | J6: 60-70 | K6: Not started
A7: 5 | B7: Agents, tools and MCP | C7: =IF(Dashboard!$C$7="","",EDATE(Dashboard!$C$7,A7-1)) | D7: =IF(C7="","",EDATE(C7,1)-1) | E7: Project 3 shipped | F7: Build a tool-using agent with state, permissions and human approval, connected through MCP. | G7: Project 3: Tool-using agent | H7: Agent repo + MCP server + task success benchmark (20+ tasks, 5 runs each) + threat notes | I7: pass^1 and pass^5 reported on 20 tasks; approval gate demo; explain one failure trajectory. Level 3 on S28-S31. | J7: 60-70 | K7: Not started
A8: 6 | B8: Evaluation as an engineering system | C8: =IF(Dashboard!$C$7="","",EDATE(Dashboard!$C$7,A8-1)) | D8: =IF(C8="","",EDATE(C8,1)-1) | E8: 6-month milestone: production-ready portfolio + interview preparation starts | F8: Build a reusable evaluation harness and put quality gates into CI for Projects 2 and 3. | G8: Project 4: Reusable evaluation harness | H8: Eval harness package + CI workflow blocking regressions + eval dashboard screenshot | I8: CI fails on a deliberately broken prompt; judge agreement >= 80% with your labels. Start interview question bank: 5 questions/day. | J8: 60-70 | K8: Not started
A9: 7 | B9: Production hardening and AI security | C9: =IF(Dashboard!$C$7="","",EDATE(Dashboard!$C$7,A9-1)) | D9: =IF(C9="","",EDATE(C9,1)-1) | E9: Project 6 shipped | F9: Turn one project into a service you would trust with real users: auth, observability, cost controls, security testing. | G9: Project 6: Production AI service (hardened P2 or P3) | H9: Deployed service + dashboards + threat model + red-team report + runbook + cost report | I9: Run the production readiness checklist; all critical items pass. Level 3 on S40-S46. | J9: 60-70 | K9: Not started
A10: 8 | B10: Multimodal AI and fine-tuning | C10: =IF(Dashboard!$C$7="","",EDATE(Dashboard!$C$7,A10-1)) | D10: =IF(C10="","",EDATE(C10,1)-1) | E10: Project 5 shipped | F10: Build a document, vision or voice AI system and learn when fine-tuning beats prompting. | G10: Project 5: Multimodal system (document intelligence, visual QA, or voice agent) | H10: Repo + field-level accuracy report (or latency breakdown for voice) + fine-tune vs prompt comparison | I10: Accuracy or latency targets set in advance and met or explained. Level 2-3 on S16, S32-S34. | J10: 60-70 | K10: Not started
A11: 9 | B11: AI infrastructure, advanced retrieval and capstone design | C11: =IF(Dashboard!$C$7="","",EDATE(Dashboard!$C$7,A11-1)) | D11: =IF(C11="","",EDATE(C11,1)-1) | E11: Capstone design approved | F11: Understand serving economics and design a serious capstone before writing code. | G11: Capstone design document: problem, users, data, architecture, models, retrieval, agents, evaluation plan, security, deployment, economics, risks | H11: Design doc + architecture diagram + ADRs + serving benchmark notebook | I11: Peer or mentor review of design doc using the capstone rubric. Start networking: 5 conversations this month. | J11: 60-70 | K11: Not started
A12: 10 | B12: Capstone build | C12: =IF(Dashboard!$C$7="","",EDATE(Dashboard!$C$7,A12-1)) | D12: =IF(C12="","",EDATE(C12,1)-1) | E12: Capstone core working end to end | F12: Build the capstone's core workflow with evaluation from day one. | G12: Capstone v1: core workflow, eval set, traces | H12: Working demo on staging + eval report v1 | I12: Core user journey passes 80% of eval set. Resume and LinkedIn rewritten around projects. | J12: 70-80 | K12: Not started
A13: 11 | B13: Capstone production + system design preparation | C13: =IF(Dashboard!$C$7="","",EDATE(Dashboard!$C$7,A13-1)) | D13: =IF(C13="","",EDATE(C13,1)-1) | E13: Capstone deployed | F13: Harden, secure, deploy and document the capstone; begin structured interview preparation. | G13: Capstone v2: deployed with auth, monitoring, cost tracking, red-team report and full documentation | H13: Public demo, 3-minute video, README, design doc, eval report, cost report, failure analysis | I13: Capstone rubric score >= 80%. First 20 targeted applications sent. | J13: 70-80 | K13: Not started
A14: 12 | B14: Interview sprint and job search | C14: =IF(Dashboard!$C$7="","",EDATE(Dashboard!$C$7,A14-1)) | D14: =IF(C14="","",EDATE(C14,1)-1) | E14: 12-month milestone: advanced capstone + job-ready system design | F14: Pass all 8 mock interview rounds and run a structured job search. | G14: Portfolio site or GitHub profile README linking all 7 projects | H14: Mock interview scorecards, job tracker with 50+ targeted applications, referral pipeline | I14: Score >= 3/4 on every mock round. Weekly funnel review: applications, screens, onsites, offers. | J14: 70-80 | K14: Not started

Sheet Skills Matrix
A1: ID | B1: Layer | C1: Skill | D1: Month | E1: Target level | F1: Current level (0-5) | G1: Status | H1: Evidence link | I1: Project | J1: Interview ready | K1: Evidence that proves it | L1: Notes
A2: S01 | B2: Software engineering | C2: Python (functions, classes, typing, packaging) | D2: 0-1 | E2: 3 | G2: Not started | I2: P1 | J2: No | K2: CLI + API project with type hints, tests and a pyproject.toml
A3: S02 | B3: Software engineering | C3: Git and GitHub (branches, PRs, reviews) | D3: 1 | E3: 3 | G3: Not started | I3: All | J3: No | K3: Every project developed through PRs with clear commit history
A4: S03 | B4: Software engineering | C4: HTTP APIs and FastAPI | D4: 1-2 | E4: 3 | G4: Not started | I4: P1 | J4: No | K4: Documented API with validation, error handling and OpenAPI docs
A5: S04 | B5: Software engineering | C5: Async Python and concurrency | D5: 2 | E5: 3 | G5: Not started | I5: P1 | J5: No | K5: Concurrent LLM calls with timeouts, retries and rate limiting
A6: S05 | B6: Software engineering | C6: Testing (pytest, mocks, fixtures) | D6: 2 | E6: 3 | G6: Not started | I6: P1, P6 | J6: No | K6: Test suite with >70% coverage on non-LLM logic and mocked LLM calls
A7: S06 | B7: Software engineering | C7: SQL and relational databases (Postgres) | D7: 1-2 | E7: 3 | G7: Not started | I7: P2, P6 | J7: No | K7: Schema design + queries used in a project; SQL round practice
A8: S07 | B8: Software engineering | C8: Linux, shell and networking basics | D8: 1 | E8: 2 | G8: Not started | I8: P6 | J8: No | K8: Deploy and debug a service on a Linux VM over SSH
A9: S08 | B9: Software engineering | C9: Docker and docker compose | D9: 2 | E9: 3 | G9: Not started | I9: P1-P7 | J9: No | K9: Every project runs with one docker compose up
A10: S09 | B10: Software engineering | C10: CI/CD (GitHub Actions) | D10: 6 | E10: 3 | G10: Not started | I10: P6 | J10: No | K10: Pipeline running lint, tests and evals on every PR
A11: S10 | B11: Software engineering | C11: System design fundamentals | D11: 8-11 | E11: 3 | G11: Not started | I11: P7 | J11: No | K11: Written design docs for capstone; mock system design rounds passed
A12: S11 | B12: ML foundations | C12: Probability, statistics and linear algebra for ML | D12: 2-3 | E12: 2 | G12: Not started | I12: - | J12: No | K12: Explain softmax, cosine similarity, variance, confidence intervals in your own notes
A13: S12 | B13: ML foundations | C13: Supervised/unsupervised learning and evaluation metrics | D13: 2-3 | E13: 2 | G13: Not started | I13: - | J13: No | K13: Trained classifier with proper train/val/test split and metric choice justified
... A53: S52 | B53: Career | C53: Explaining trade-offs in interviews | D53: 10-12 | E53: 3 | G53: Not started | I53: - | J53: No | K53: Recorded mock interviews scored 3+/4 on rubric

Sheet Learning Tracker
A1: Month | B1: Topic | C1: Resource IDs | D1: Resource | E1: Priority | F1: Hours spent | G1: Status | H1: Start date | I1: End date | J1: Artifact produced | K1: Notes | L1: Review date
A2: 0 | B2: On-ramp: from zero to writing Python | C2: C03, C04 | D2: C03 CS50P (or C04 Python for Everybody) | E2: High | G2: Not started
A3: 0 | B3: On-ramp: from zero to writing Python | C3: C01 | D3: C01 Elements of AI (optional) | E3: High | G3: Not started
A4: 0 | B4: On-ramp: from zero to writing Python | C4: B01 | D4: B01 Python Crash Course | E4: High | G4: Not started
A5: 0 | B5: On-ramp: from zero to writing Python | C5: Y05, Y04 | D5: Y05 CodeWithHarry (Hindi) or Y04 Corey Schafer | E5: High | G5: Not started
A6: 1 | B6: Engineering foundations and your first AI app | C6: C05 | D6: C05 Missing Semester (shell, Git, debugging) | E6: High | G6: Not started
A7: 1 | B7: Engineering foundations and your first AI app | C7: C06 | D7: C06 GitHub Skills | E7: High | G7: Not started
A8: 1 | B8: Engineering foundations and your first AI app | C8: C07 | D8: C07 Kaggle SQL | E8: High | G8: Not started
A9: 1 | B9: Engineering foundations and your first AI app | C9: T04, T05 | D9: T04 Claude API docs or T05 OpenAI Cookbook | E9: High | G9: Not started
A10: 1 | B10: Engineering foundations and your first AI app | C10: C15 | D10: C15 Anthropic Academy API course | E10: High | G10: Not started
A11: 2 | B11: LLM engineering core | C11: T40 | D11: T40 FastAPI tutorial | E11: High | G11: Not started
A12: 2 | B12: LLM engineering core | C12: T41 | D12: T41 Docker get started | E12: High | G12: Not started
A13: 2 | B13: LLM engineering core | C13: T07 | D13: T07 LiteLLM | E13: High | G13: Not started
... A65: 9 | B65: AI infrastructure, advanced retrieval and capstone design | C65: B19 | D65: B19 DDIA selected chapters | E65: Medium | G65: Not started
A66: 10 | B66: Capstone build | D66: Your own design doc | E66: Medium | G66: Not started
A67: 10 | B67: Capstone build | D67: docs for chosen stack | E67: Medium | G67: Not started
A68: 10 | B68: Capstone build | C68: B22 | D68: B22 Generative AI System Design Interview (start) | E68: Medium | G68: Not started
A69: 11 | B69: Capstone production + system design preparation | C69: B22 | D69: B22 Generative AI System Design Interview | E69: Medium | G69: Not started
A70: 11 | B70: Capstone production + system design preparation | C70: B21 | D70: B21 System Design Interview (selected) | E70: Medium | G70: Not started
A71: 11 | B71: Capstone production + system design preparation | C71: Y19 | D71: Y19 ByteByteGo | E71: Medium | G71: Not started
A72: 11 | B72: Capstone production + system design preparation | D72: interview question bank (daily) | E72: Medium | G72: Not started
A73: 12 | B73: Interview sprint and job search | D73: Question bank (all categories) | E73: Medium | G73: Not started
A74: 12 | B74: Interview sprint and job search | C74: B06, B12 | D74: B06 and B12 for revision | E74: Medium | G74: Not started
A75: 12 | B75: Interview sprint and job search | D75: mock interview scripts in this playbook | E75: Medium | G75: Not started

Sheet Projects
A1: ID | B1: Project | C1: Month | D1: Objective | E1: Repo link | F1: Demo link | G1: Architecture diagram | H1: Skills demonstrated | I1: Deployment URL | J1: Evaluation report | K1: Documentation | L1: Status | M1: Interview ready | N1: Acceptance criteria
A2: P1 | B2: Production-style AI API (model comparison service) | C2: 2 | D2: Prove you can integrate foundation models like a software engineer: typed inputs and outputs, retries, tests, containers and measured trade-offs. | L2: Not started | M2: No | N2: ☐ docker compose up starts everything with only an .env file ☐ Invalid LLM JSON is caught and retried; failure returns a clear 4xx/5xx ☐ Benchmark table covers 50 examples x 3 models with accuracy, p50/p95 latency and cost ☐ Unit tests run without network (LLM calls mocked) ☐ README explains when you would choose each model
A3: P2 | B3: Evaluated RAG application | C3: 4 | D3: Show you can build retrieval that works on messy real documents and prove quality with numbers, not screenshots. | L3: Not started | M3: No | N3: ☐ Golden set of 100 questions including 15 unanswerable ones ☐ Experiment table with at least 4 configurations and recall@5, MRR, faithfulness, latency, cost ☐ Every answer shows citations that open the right source ☐ Unanswerable questions correctly refused at least 80% of the time ☐ Evaluation report explains the chosen configuration and two remaining failure modes
A4: P3 | B4: Tool-using agent | C4: 5 | D4: Show you can design an agent that is reliable, observable and safe, and justify why an agent was needed at all. | L4: Not started | M4: No | N4: ☐ Design doc explains why workflow steps vs agent steps ☐ MCP server usable from at least one other MCP client ☐ Benchmark of 20+ tasks run 5 times each with pass^1 and pass^5 ☐ Destructive tool never executes without approval (tested) ☐ Failure analysis categorizes at least 10 failed runs
A5: P4 | B5: Reusable evaluation harness | C5: 6 | D5: Demonstrate evaluation as an engineering discipline: datasets, metrics, validated judges and CI gates, reused across your projects. | L5: Not started | M5: No | N5: ☐ Harness evaluates at least two different projects (P2 and P3) ☐ LLM judge agreement with human labels reported (target >= 80%) ☐ CI blocks a PR that deliberately degrades a prompt ☐ Report shows per-category scores, not just an average ☐ Docs explain how to add a new scorer in under 30 lines
A6: P5 | B6: Multimodal system | C6: 8 | D6: Show you can handle real-world inputs that are not clean text and measure accuracy or latency where it matters. | L6: Not started | M6: No | N6: ☐ A: field-level precision/recall per field on 50+ documents; low-confidence routing to human review ☐ C: end-to-end response latency p50 and p95 with per-stage breakdown; barge-in works ☐ Cost per document or per minute of conversation reported ☐ Failure gallery with 10 annotated examples
A7: P6 | B7: Production AI service | C7: 7 | D7: Prove you can operate an AI system, not just build it: the gap most portfolios never close. | L7: Not started | M7: No | N7: ☐ Unauthenticated requests rejected; users cannot access each other's data (tested) ☐ Dashboard shows p50/p95 latency, error rate, cost per request per user ☐ Simulated provider outage handled by fallback without user-facing errors ☐ Prompt rollback demonstrated in under 5 minutes ☐ Red-team report lists attacks, results, mitigations and residual risk ☐ Monthly cost estimate at 100, 1,000 and 10,000 daily users
A8: P7 | B8: Capstone: serious domain-specific system | C8: 9-12 | D8: Create the single strongest piece of evidence in your job search and the centre of your final interview round. | L8: Not started | M8: No | N8: ☐ Passes the capstone rubric at 80% or higher ☐ Real or realistic data, not toy examples ☐ Deployed demo, 3-minute video and full documentation ☐ Defensible answers to every capstone defence question

Sheet Capstone
B1: Capstone command centre
B2: Project title:
B3: Design doc link:
A5: # | B5: Stage | C5: Questions to answer | D5: My answer / link | E5: Status
A6: 1 | B6: Problem | C6: What painful problem? How is it solved today? Success in numbers? | E6: Not started
A7: 2 | B7: Users | C7: Who exactly? What do they need? What makes them stop using it? | E7: Not started
A8: 3 | B8: Data | C8: Sources, volume, format, quality, licensing, freshness, privacy | E8: Not started
A9: 4 | B9: Architecture | C9: Components, data flow, sync vs async, where state lives | E9: Not started
A10: 5 | B10: Models | C10: Which models for which steps? Why? Fallbacks? | E10: Not started
A11: 6 | B11: Retrieval | C11: What is retrieved, how indexed, how quality is measured | E11: Not started
A12: 7 | B12: Agents / tools | C12: Workflow vs model judgment; tools and permissions | E12: Not started
A13: 8 | B13: Evaluation | C13: Datasets, metrics, human review, thresholds, regression gates | E13: Not started
A14: 9 | B14: Security | C14: Threat model, injection, authorization, data protection, audit | E14: Not started
A15: 10 | B15: Deployment | C15: Where it runs, environments, CI/CD, rollback | E15: Not started
A16: 11 | B16: Observability | C16: Traces, metrics, alerts, dashboards; debugging a bad output | E16: Not started
A17: 12 | B17: Economics | C17: Cost per task; monthly cost at 3 scales; value created | E17: Not started
... A20: 15 | B20: Documentation | C20: README, architecture, ADRs, evaluation report, runbook, limitations | E20: Not started
B23: Capstone rubric (0 / 2 / 4 per area, target 48+)
A24: # | B24: Area | C24: Score (0, 2 or 4) | D24: Evidence / what to improve
A25: 1 | B25: Problem and users
A26: 2 | B26: Data
A27: 3 | B27: Architecture
A28: 4 | B28: Model choices
A29: 5 | B29: Retrieval
A30: 6 | B30: Agents and tools
A31: 7 | B31: Evaluation
A32: 8 | B32: Security
A33: 9 | B33: Deployment
A34: 10 | B34: Observability
A35: 11 | B35: Economics
A36: 12 | B36: Failure handling
... A39: 15 | B39: Defence readiness
B40: Total | C40: =SUM(C25:C39)

Sheet Capstone Ideas
A1: ID | B1: Domain | C1: Title | D1: Difficulty | E1: Problem | F1: Users | G1: Data | H1: Workflow | I1: Techniques | J1: Evaluation | K1: Security | L1: Economics | M1: Failure modes | N1: India angle | O1: Shortlist?
A2: K01 | B2: Healthcare | C2: Clinical discharge summary copilot | D2: Advanced | E2: Doctors spend 20-40 minutes writing discharge summaries from scattered notes, labs and medication lists; errors in medication instructions cause readmissions. | F2: Resident doctors, nurses, hospital quality teams | G2: Synthea synthetic patient records (synthetichealth.github.io/synthea); openFDA drug labels (open.fda.gov); public clinical guidelines | H2: Pull patient timeline -> extract diagnoses, procedures, meds -> check drug interactions against labels -> draft summary with citations to source notes -> doctor edits and approves -> patient-friendly version in English/Hindi/Telugu | I2: Structured extraction, RAG over guidelines and labels, tool calls for interaction checks, human approval, multilingual generation | J2: Clinician-style rubric on 50 cases (completeness, correctness, citation accuracy); medication error detection recall; edit distance between draft and approved summary | K2: PHI handling, access by role, audit trail, no autonomous final output, DPDP Act-aware data handling | L2: Cost per summary vs doctor time saved | M2: Hallucinated medications, missed allergies, outdated guidelines | N2: Multilingual patient instructions; relevant to Hyderabad hospital chains and health-tech GCCs
A3: K02 | B3: Pharma / life sciences | C3: Pharmacovigilance signal triage agent | D3: Advanced | E3: Safety teams manually read thousands of adverse event reports and literature to spot drug safety signals. | F3: Drug safety scientists at pharma companies and their GCCs | G3: openFDA FAERS adverse event data (open.fda.gov); PubMed abstracts via NCBI E-utilities; public drug labels | H3: Ingest reports -> normalize drug and event terms -> cluster similar cases -> retrieve literature evidence -> draft case narrative and signal assessment -> scientist review queue | I3: Entity extraction and normalization, clustering with embeddings, agentic literature search, structured reports | J3: Term normalization accuracy; retrieval precision on 40 known drug-event pairs; reviewer agreement with triage priority | K3: Audit logs, reproducibility of every assessment, model and prompt version stamped on each output | L3: Cases triaged per hour; cost per case | M3: Wrong term mapping, missing duplicates, over-confident causality statements | N3: Hyderabad hosts major pharma GCCs (Novartis, Eli Lilly, Sanofi and others); strong local interview story
A4: K03 | B4: Legal | C4: Indian case-law research assistant | D4: Advanced | E4: Junior lawyers spend hours finding relevant precedents and statutes and often miss overruled judgments. | F4: Junior advocates, law students, in-house legal teams | G4: India Code (indiacode.nic.in) for central Acts; public Supreme Court judgment datasets (for example the Indian Supreme Court Judgments dataset on AWS Open Data) | H4: Question -> identify legal issues -> hybrid search over statutes and judgments -> citation graph check (cited, followed, overruled) -> answer memo with pinpoint citations -> lawyer verification | I4: Long-document parsing, hybrid retrieval, citation graph (GraphRAG), structured memos, refusal when evidence is weak | J4: Citation accuracy (does the paragraph say what the memo claims), recall of known leading cases on 40 questions, hallucinated citation rate (target 0) | K4: No legal advice framing, client data isolation, audit trail | L4: Research time saved per memo; retrieval cost at corpus scale | M4: Fabricated citations, overruled precedent cited as good law | N4: Large Indian legal-tech opportunity; strong demo for Bengaluru and NCR startups
A5: K04 | B5: Finance | C5: Annual report and filing analyst | D5: Advanced | E5: Analysts manually compare companies' filings to find risk changes, related-party transactions and guidance shifts. | F5: Equity research analysts, credit analysts, finance students | G5: Annual reports of listed Indian companies (BSE/NSE company pages); SEC EDGAR filings for global comparison; RBI and SEBI circulars | H5: Ingest filings with tables -> extract key metrics and risk sections -> year-over-year diff -> answer analyst questions with table citations -> generate one-page brief | I5: Table extraction, numeric validation with code execution, RAG over long documents, diffing agent | J5: Numeric extraction accuracy vs hand-checked values on 30 companies; faithfulness of risk summaries; calculation correctness | K5: Clear non-advice framing; data licensing check; prompt injection via filings | L5: Cost per company brief | M5: Unit errors (lakhs vs crores vs millions), misread tables, stale data | N5: Unit handling for Indian number formats is a real differentiator
A6: K05 | B6: Cybersecurity | C6: SOC alert triage and vulnerability prioritization agent | D6: Advanced | E6: Security operations teams face alert fatigue and cannot prioritize thousands of CVEs. | F6: SOC analysts, vulnerability management teams | G6: NVD CVE feeds (nvd.nist.gov); CISA Known Exploited Vulnerabilities catalog; MITRE ATT&CK; synthetic alert logs | H6: Alert or scan result -> enrich with CVE, KEV and ATT&CK context -> check asset inventory (tool) -> risk score with reasoning -> recommended action -> analyst approval -> ticket creation | I6: Tool-using agent, structured enrichment, retrieval over threat intel, approval gates | J6: Priority agreement with analyst labels on 100 alerts; false negative rate on known-exploited CVEs; time to triage | K6: Agent itself is a high-value target: strict tool permissions, no remediation without approval, full audit log | L6: Analyst hours saved; cost per triaged alert | M6: Missing a critical exploited vulnerability; injection via log content | N6: Hyderabad cybersecurity GCCs and MSSPs
A7: K06 | B7: Manufacturing | C7: Maintenance technician copilot | D7: Intermediate-Advanced | E7: Technicians lose time searching manuals and past work orders; knowledge leaves with senior staff. | F7: Maintenance technicians, plant engineers | G7: Public equipment manuals (PDF); synthetic maintenance logs; NASA prognostics datasets for sensor context | H7: Technician describes symptom by voice or photo -> retrieve manual sections and similar past work orders -> guided troubleshooting steps -> log resolution -> update knowledge base | I7: Multimodal input (photo of error panel), RAG over manuals, similar-case retrieval, voice interface option | J7: Correct procedure retrieval on 50 symptom scenarios; step accuracy reviewed against manuals; resolution logging completeness | K7: Safety-critical disclaimers, lockout/tagout steps never skipped, offline mode considerations | L7: Mean time to repair reduction estimate | M7: Wrong model variant manual, unsafe step ordering | N7: Relevant to Pune and Chennai manufacturing and Hyderabad aerospace/defence suppliers
A8: K07 | B8: Retail / e-commerce | C8: Multilingual product catalog and support agent | D8: Intermediate | E8: Sellers write poor product listings and support teams handle repetitive order queries in many languages. | F8: Small online sellers, e-commerce support teams | G8: Amazon Reviews 2023 dataset (McAuley Lab) for products and reviews; synthetic order database | H8: Seller uploads photos + notes -> generate listing with attributes -> quality checks. Customer query -> order lookup tool -> policy retrieval -> answer or escalate -> refund approval gate | I8: Vision-language extraction, structured attributes, support agent with tools, Indian language support | J8: Attribute accuracy on 100 products; support task success and escalation correctness on 50 scenarios; language quality review | K8: Refund fraud attempts via prompt injection; PII in chats | L8: Cost per listing and per resolved ticket vs human agent | M8: Wrong attribute claims, refunds approved outside policy | N8: Code-mixed Hinglish and regional language queries
A9: K08 | B9: Education | C9: NCERT-aligned tutor with learning diagnostics | D9: Intermediate | E9: Students need practice and explanations at their level; teachers cannot personalize for 40+ students. | F9: School students (Class 8-12), teachers | G9: NCERT textbooks (free PDFs at ncert.nic.in); previous board exam question styles (public) | H9: Student asks or takes diagnostic quiz -> retrieve chapter content -> Socratic hint rather than direct answer -> generate practice questions -> track concept mastery -> teacher dashboard | I9: RAG over textbooks, question generation with answer verification, learner model, guardrails for age-appropriate content | J9: Answer correctness on 200 textbook questions; generated question validity reviewed by a teacher; hint quality rubric | K9: Minor safety, no data selling, parental/teacher visibility | L9: Cost per student per month at scale | M9: Wrong answers stated confidently, giving away answers, syllabus drift | N9: Hindi/Telugu explanations; large market; strong for ed-tech interviews
A10: K09 | B10: Developer tools | C10: Pull request review and test generation agent | D10: Advanced | E10: Code reviews are slow and inconsistent; test coverage lags. | F10: Engineering teams | G10: Public GitHub repositories and their PR history; SWE-bench style tasks for evaluation | H10: PR opened -> fetch diff and related files -> static checks -> review comments with severity -> propose tests -> run tests in sandbox -> post summary | I10: Code retrieval, sandboxed execution, GitHub integration via MCP or API, structured review output | J10: Precision of review comments against human reviewer labels on 50 PRs; generated test pass rate and mutation score; noise rate | K10: Sandboxing, repository secrets never exposed, prompt injection via code comments | L10: Cost per PR; reviewer time saved | M10: Noisy comments, tests that pass trivially, missing real bugs | N10: Strong fit for product companies and developer-tool startups
A11: K10 | B11: Enterprise productivity | C11: Meeting-to-action workflow agent | D11: Intermediate | E11: Decisions and action items from meetings get lost; follow-ups are manual. | F11: Project managers, team leads | G11: Public meeting transcript datasets (for example AMI Meeting Corpus); synthetic Jira/Slack workspace | H11: Transcript -> extract decisions, owners, deadlines -> check existing tickets (tool) -> propose new or updated tickets -> manager approval -> post summary to team channel | I11: Structured extraction, entity resolution of people and projects, MCP connectors to ticketing and chat, approvals | J11: Action-item precision/recall on 30 labelled meetings; owner and deadline accuracy; duplicate ticket rate | K11: Permission-aware access to channels and tickets; confidential meeting handling | L11: Cost per meeting processed | M11: Wrong owner assignment, duplicate tickets, leaking private channel content | N11: Common GCC internal tooling request
A12: K11 | B12: Climate / agriculture | C12: Farmer advisory voice assistant | D12: Advanced | E12: Small farmers lack timely, local, language-appropriate advice on weather, pests and crop practices. | F12: Farmers, Krishi Vigyan Kendra staff, FPOs | G12: Open-Meteo weather API; state agriculture department and ICAR package-of-practices documents (public PDFs); crop price data from data.gov.in | H12: Farmer calls or sends voice note in Telugu/Hindi -> speech to text -> identify crop, stage, location -> weather tool + practice retrieval -> short spoken advice -> escalate to human expert for pest images or uncertain cases | I12: Voice pipeline, Indian language STT/TTS, RAG over agricultural documents, weather tools, image-based pest check (stretch) | J12: Advice correctness reviewed against documents on 60 scenarios; STT word error rate on local speech; latency | K12: No pesticide dosage without source citation; human escalation; low-literacy UX | L12: Cost per call; feasibility on low-bandwidth networks | M12: Wrong dosage, dialect misrecognition, outdated weather | N12: High social impact; aligns with state AI missions and grand challenges
A13: K12 | B13: Public sector | C13: Government scheme eligibility and application assistant | D13: Intermediate-Advanced | E13: Citizens miss benefits because scheme rules are complex and spread across portals. | F13: Citizens, Common Service Centre operators, NGOs | G13: myScheme portal (myscheme.gov.in) scheme descriptions; data.gov.in; state scheme PDFs | H13: Conversational profile collection -> rules-based eligibility check (deterministic code, not LLM) -> retrieve scheme details with citations -> document checklist -> guided application steps -> operator handoff | I13: Hybrid: LLM for conversation and extraction, deterministic rules engine for eligibility, RAG with citations, multilingual | J13: Eligibility accuracy on 100 synthetic citizen profiles vs hand-computed rules; citation correctness; task completion | K13: Minimal personal data collection, consent, no Aadhaar storage, DPDP Act-aware design | L13: Cost per citizen session at state scale | M13: Wrong eligibility decision, stale scheme rules | N13: Shows judgment: LLM where language matters, code where rules matter

Sheet GitHub
A1: Repo name | B1: Project | C1: Repo link | D1: Pinned | E1: Description + topics | F1: README complete | G1: Architecture diagram | H1: Results table | I1: CI passing | J1: Demo link | K1: Licence | L1: No secrets (scanned) | M1: Last updated | N1: Notes
B2: P1 Production-style AI API (model comparison service) | D2: No | E2: No | F2: No | G2: No | H2: No | I2: No | K2: No | L2: No
B3: P2 Evaluated RAG application | D3: No | E3: No | F3: No | G3: No | H3: No | I3: No | K3: No | L3: No
B4: P3 Tool-using agent | D4: No | E4: No | F4: No | G4: No | H4: No | I4: No | K4: No | L4: No
B5: P4 Reusable evaluation harness | D5: No | E5: No | F5: No | G5: No | H5: No | I5: No | K5: No | L5: No
B6: P5 Multimodal system | D6: No | E6: No | F6: No | G6: No | H6: No | I6: No | K6: No | L6: No
B7: P6 Production AI service | D7: No | E7: No | F7: No | G7: No | H7: No | I7: No | K7: No | L7: No
B8: P7 Capstone: serious domain-specific system | D8: No | E8: No | F8: No | G8: No | H8: No | I8: No | K8: No | L8: No
A9: profile README | B9: GitHub profile | D9: n/a | E9: No | F9: No | G9: n/a | H9: n/a | I9: n/a | K9: n/a | L9: n/a

Sheet Question Bank
A1: ID | B1: Category | C1: Difficulty | D1: Question | E1: Expected concepts | F1: Strong answer | G1: Weak answer | H1: Follow-ups and common mistakes | I1: Confidence (1-3) | J1: Last practised | K1: Next review | L1: My notes
A2: FND-01 | B2: Foundational engineering | C2: Easy | D2: What is the difference between a list and a tuple in Python, and when would you use each? | E2: mutability, hashability, intent, performance | F2: A list is mutable; a tuple is immutable. Because tuples cannot change, they are hashable when their elements are hashable, so they can be dict keys or set members (for example a cache key of `(model, prompt_hash)`). I use tuples for fixed-shape records and to signal that data should not change, and lists for collections that grow or get modified, like a batch of chunks being built. Tuples are slightly smaller and faster to create, but the main reason to choose one is intent and hashability, not speed. | G2: Tuples use round brackets and lists use square brackets; tuples are faster. | H2: • Can a tuple containing a list be used as a dict key? • When would you use a NamedTuple or dataclass instead? Common mistakes: • Claiming tuples are always deeply immutable • Choosing based only on micro-performance | K2: =IF(J2="","",J2+IF(I2=1,3,IF(I2=2,7,14)))
A3: FND-02 | B3: Foundational engineering | C3: Medium | D3: What is the GIL, and does it matter when your service makes many concurrent LLM API calls? | E3: Global Interpreter Lock, I/O-bound vs CPU-bound, asyncio, threads, multiprocessing | F3: The GIL lets only one thread execute Python bytecode at a time in CPython. It matters for CPU-bound work, but LLM API calls are I/O-bound: the thread spends most of its time waiting on the network, and the GIL is released during I/O. So asyncio or threads give real concurrency for API calls. For CPU-heavy steps such as local embedding computation, PDF parsing or tokenization at scale, I would use multiprocessing, native libraries that release the GIL, or a separate worker service. Free-threaded Python builds are emerging, but I would not design around them yet for production. | G3: The GIL makes Python single-threaded, so you need multiprocessing for concurrent API calls. | H3: • How would you cap concurrency to respect provider rate limits? • Where in a RAG ingestion pipeline is the work CPU-bound? Common mistakes: • Saying Python cannot do concurrent network calls • Using multiprocessing for pure I/O work | K3: =IF(J3="","",J3+IF(I3=1,3,IF(I3=2,7,14)))
A4: FND-03 | B4: Foundational engineering | C4: Medium | D4: You need to send 500 prompts to an LLM API as fast as possible without getting rate limited. How do you implement it? | E4: asyncio, semaphore, rate limiting, retries with backoff, batch APIs | F4: I would use an async HTTP client with `asyncio.gather` over tasks, bounded by an `asyncio.Semaphore` sized to the provider's concurrency limit, plus a token-bucket limiter for requests or tokens per minute. Each call gets a timeout and retries with exponential backoff and jitter on 429 and 5xx, honouring any `Retry-After` header. Results are written incrementally so a crash does not lose progress, and each prompt has an ID so retries are idempotent. If results are not needed immediately, I would use the provider's batch API instead, which is usually cheaper and avoids rate-limit engineering entirely. | G4: Loop through the prompts with a for loop and add time.sleep between calls. | H4: • How do you choose the semaphore size? • How would you resume after a crash halfway through? Common mistakes: • Unbounded gather causing a burst of 429s • Retrying without jitter, causing synchronized retry storms • Ignoring batch APIs for offline jobs | K4: =IF(J4="","",J4+IF(I4=1,3,IF(I4=2,7,14)))
A5: FND-04 | B5: Foundational engineering | C5: Medium | D5: Implement retry logic for an unreliable API. What should and should not be retried? | E5: exponential backoff, jitter, idempotency, retryable status codes, total timeout | F5: Retry only transient failures: timeouts, connection errors, 429 and most 5xx (500, 502, 503, 504). Do not retry 400, 401, 403, 404 or validation errors, because the same request will fail again. Use exponential backoff with full jitter, for example `sleep = random.uniform(0, base * 2**attempt)` capped at a maximum, a limited number of attempts, and an overall deadline so retries cannot exceed the user's latency budget. Honour `Retry-After` when present. Only retry non-idempotent operations such as payments or refunds if the request carries an idempotency key. Log every retry with the reason so retry-driven cost increases are visible. | G5: Wrap the call in try/except and retry three times. | H5: • Why is jitter important? • How do retries interact with LLM cost? • Where would you put a circuit breaker? Common mistakes: • Retrying 4xx errors • No overall deadline • Retrying side-effecting calls without idempotency | K5: =IF(J5="","",J5+IF(I5=1,3,IF(I5=2,7,14)))
A6: FND-05 | B6: Foundational engineering | C6: Easy | D6: What is a Python generator, and why is it useful when streaming LLM responses? | E6: yield, lazy evaluation, memory, async generators, streaming | F6: A generator is a function that uses `yield` to produce values one at a time, pausing between them, instead of building a full list in memory. For streaming LLM output, an (async) generator can yield tokens or chunks as they arrive from the provider, and a FastAPI `StreamingResponse` can forward them to the client immediately. This reduces time to first token for the user and keeps memory flat. Generators also work well for processing large document sets lazily during ingestion. | G6: A generator creates values using a for loop. | H6: • How do you handle an error that happens midway through a stream? • How would you also compute total tokens for billing while streaming? Common mistakes: • Collecting the entire stream before returning it • Forgetting async generators for async clients | K6: =IF(J6="","",J6+IF(I6=1,3,IF(I6=2,7,14)))
A7: FND-06 | B7: Foundational engineering | C7: Easy | D7: What is a decorator? Write one that measures the latency of a function. | E7: higher-order functions, functools.wraps, async support, observability | F7: A decorator is a function that takes a function and returns a wrapped version with extra behaviour. ```python import time, functools def timed(fn): @functools.wraps(fn) async def wrapper(*args, **kwargs): start = time.perf_counter() try: return await fn(*args, **kwargs) finally: logger.info('latency', extra={'fn': fn.__name__, 'ms': (time.perf_counter() - start) * 1000}) return wrapper ``` `functools.wraps` preserves the name and docstring, `perf_counter` is the right clock for durations, and `finally` records latency even on errors. In production I would emit this as a tracing span rather than a log line. | G7: A decorator is the @ symbol that adds features to a function. | H7: • How would you make it work for both sync and async functions? • How would you pass arguments to the decorator? Common mistakes: • Using time.time() for durations • Forgetting functools.wraps • Not recording failures | K7: =IF(J7="","",J7+IF(I7=1,3,IF(I7=2,7,14)))
A8: FND-07 | B8: Foundational engineering | C8: Easy | D8: What does Pydantic do, and why is it so common in AI applications? | E8: data validation, type hints, JSON Schema, structured outputs, FastAPI | F8: Pydantic validates and parses data into typed Python objects based on type hints, raising clear errors when data does not match. In AI apps it does three jobs: validating API request and response bodies (FastAPI is built on it), defining the schema for structured LLM outputs and tool arguments (Pydantic models export JSON Schema that providers accept), and validating what the model actually returned before the rest of the system trusts it. That turns 'the model returned something weird' into a caught, retryable validation error. | G8: Pydantic is a library for making classes. | H8: • What would you do when the model output fails validation twice? • How do you express an enum or constrained string? Common mistakes: • Trusting model JSON without validation • Overly permissive schemas (everything Optional[str]) | K8: =IF(J8="","",J8+IF(I8=1,3,IF(I8=2,7,14)))
A9: FND-08 | B9: Foundational engineering | C9: Easy | D9: Explain the differences between POST, PUT and PATCH. Which are idempotent? | E9: HTTP semantics, idempotency, API design | F9: POST creates a resource or triggers an action; it is not idempotent by default, so repeating it can create duplicates. PUT replaces a resource at a known URI with the full representation; repeating it leaves the same state, so it is idempotent. PATCH applies a partial update; it may or may not be idempotent depending on the operation (setting a field is, incrementing a counter is not). GET, PUT and DELETE are defined as idempotent. For AI endpoints that trigger side effects, like an agent creating a ticket, I make POST safe to retry with an idempotency key. | G9: POST adds data, PUT updates data, PATCH also updates data. | H9: • Is DELETE idempotent if the second call returns 404? • How would you design an endpoint that starts a long-running agent task? Common mistakes: • Saying PATCH is always idempotent • Using GET for actions with side effects | K9: =IF(J9="","",J9+IF(I9=1,3,IF(I9=2,7,14)))
A10: FND-09 | B10: Foundational engineering | C10: Medium | D10: Your service calls an LLM provider. For each status code, would you retry: 400, 401, 403, 404, 408, 409, 422, 429, 500, 502, 503, 504? | E10: status code semantics, transient vs permanent errors, rate limiting | F10: Retry: 408 (request timeout), 429 (rate limited, respecting Retry-After), 500, 502, 503 and 504, since they are usually transient. Do not retry: 400 and 422 (the request is malformed, for example context too long or invalid schema; fix the request instead), 401 (bad credentials), 403 (not permitted), 404 (wrong endpoint or model name). 409 depends on the API; it signals a conflict that usually needs logic, not a blind retry. For 400s caused by context length, the right reaction is to truncate or summarize context and try again deliberately, which is a different code path from a retry. | G10: Retry all errors a few times because APIs are flaky. | H10: • What would you alert on? • How do you distinguish a provider outage from your own bug? Common mistakes: • Retrying 401/403 • Treating context-length errors as transient | K10: =IF(J10="","",J10+IF(I10=1,3,IF(I10=2,7,14)))
A11: FND-10 | B11: Foundational engineering | C11: Medium | D11: How do you stream LLM tokens to a web client? Compare Server-Sent Events and WebSockets. | E11: SSE, WebSockets, chunked transfer, proxies and buffering, backpressure | F11: Server-Sent Events send a one-way stream of text events over a normal HTTP response; they are simple, work through most proxies, auto-reconnect in browsers, and fit the common case of streaming a model's answer. WebSockets give full-duplex communication, which is useful when the client also sends events mid-stream, such as interrupting a voice agent or collaborative sessions, but they need more infrastructure care. For a chat or RAG answer I use SSE via a streaming response. Practical gotchas: disable buffering in reverse proxies, send heartbeats to keep idle connections alive, and emit a final event with usage and citations so the client knows the stream finished cleanly. | G11: Use WebSockets because they are real-time. | H11: • How do you show citations that are only known at the end? • How do you handle client disconnects to stop paying for tokens? Common mistakes: • Ignoring proxy buffering • Not cancelling the upstream generation when the client disconnects | K11: =IF(J11="","",J11+IF(I11=1,3,IF(I11=2,7,14)))
A12: FND-11 | B12: Foundational engineering | C12: Medium | D12: Design a rate limiter that limits each user to 60 LLM requests per minute and 100,000 tokens per day. | E12: token bucket, sliding window, Redis, atomic operations, distributed systems | F12: I would use a token bucket per user for requests (capacity 60, refill 1 per second) and a daily token counter for usage. With multiple API instances, state must be shared, so I would store it in Redis and update it atomically with a Lua script or `INCRBY` plus expiry. Request limits are checked before calling the model. Token limits need care because output tokens are unknown upfront: reserve an estimate (input tokens plus max output tokens) before the call and reconcile with actual usage after. Return 429 with Retry-After and remaining quota headers. For fairness at scale, also add a global limiter below the provider's account limits. | G12: Keep a counter in a Python dictionary and reset it every minute. | H12: • Fixed window vs sliding window vs token bucket: trade-offs? • What happens if Redis is down? Common mistakes: • In-memory counters with multiple instances • Only counting requests when cost is driven by tokens | K12: =IF(J12="","",J12+IF(I12=1,3,IF(I12=2,7,14)))
A13: FND-12 | B13: Foundational engineering | C13: Medium | D13: What is an idempotency key and why would an AI agent need one? | E13: idempotency, retries, exactly-once effects, deduplication | F13: An idempotency key is a unique ID the client sends with a side-effecting request; the server stores the key with the result, and if the same key arrives again it returns the stored result instead of repeating the action. Agents need this because they retry: a tool call might time out after the refund was actually issued, the agent or framework retries, and without a key the customer gets two refunds. I generate the key deterministically from the task and step (for example `run_id:step:tool`), enforce it in the tool service with a unique constraint, and keep keys for longer than the maximum retry window. | G13: It is a key that makes an API secure. | H13: • Where should the key be generated, by the model or by code? • How long do you keep keys? Common mistakes: • Letting the model generate the key • Relying on 'the model will not call twice' | K13: =IF(J13="","",J13+IF(I13=1,3,IF(I13=2,7,14)))
... A301: BEH-25 | B301: Behavioural | C301: Easy | D301: Do you have any questions for us? | E301: genuine curiosity, role clarity, engineering maturity signals, team culture | F301: Ask questions that show you understand what makes AI teams succeed and help you evaluate the role: 'How do you evaluate AI features before release, and who owns evaluation?' 'What does production monitoring look like for your AI systems today?' 'What is the biggest reliability or cost challenge the team faces with its current AI features?' 'How are decisions made between building with APIs and self-hosting?' 'What would success look like for this role in the first 90 days?' 'How does the team handle AI security and data privacy reviews?' Choose two or three based on the conversation. | G301: No, I think you covered everything. | H301: • (Interviewer observes the quality of your questions) Common mistakes: • No questions • Only asking about salary or leave at this stage | K301: =IF(J301="","",J301+IF(I301=1,3,IF(I301=2,7,14)))

Sheet Mock Interviews
A1: Loop | B1: Round | C1: Date | D1: Interviewer | E1: Score 1 | F1: Score 2 | G1: Score 3 | H1: Score 4 | I1: Score 5 | J1: Score 6 | K1: Score 7 | L1: Score 8 | M1: Rubric lines scored | N1: Average | O1: What went well | P1: What to fix | Q1: Next date
A2: 1 | B2: 1 Coding | N2: =IFERROR(ROUND(AVERAGE(E2:L2),2),"")
A3: 1 | B3: 2 AI fundamentals | N3: =IFERROR(ROUND(AVERAGE(E3:L3),2),"")
A4: 1 | B4: 3 LLM and RAG | N4: =IFERROR(ROUND(AVERAGE(E4:L4),2),"")
A5: 1 | B5: 4 Agent engineering | N5: =IFERROR(ROUND(AVERAGE(E5:L5),2),"")
A6: 1 | B6: 5 System design | N6: =IFERROR(ROUND(AVERAGE(E6:L6),2),"")
A7: 1 | B7: 6 Production and debugging | N7: =IFERROR(ROUND(AVERAGE(E7:L7),2),"")
A8: 1 | B8: 7 Behavioural | N8: =IFERROR(ROUND(AVERAGE(E8:L8),2),"")
A9: 1 | B9: 8 Capstone defence | N9: =IFERROR(ROUND(AVERAGE(E9:L9),2),"")
A10: 2 | B10: 1 Coding | N10: =IFERROR(ROUND(AVERAGE(E10:L10),2),"")
A11: 2 | B11: 2 AI fundamentals | N11: =IFERROR(ROUND(AVERAGE(E11:L11),2),"")
A12: 2 | B12: 3 LLM and RAG | N12: =IFERROR(ROUND(AVERAGE(E12:L12),2),"")
A13: 2 | B13: 4 Agent engineering | N13: =IFERROR(ROUND(AVERAGE(E13:L13),2),"")
... A17: 2 | B17: 8 Capstone defence | N17: =IFERROR(ROUND(AVERAGE(E17:L17),2),"")

Sheet Job Research
A1: Title | B1: Company | C1: Company type | D1: City | E1: Seniority | F1: Years required | G1: Required skills | H1: Preferred skills | I1: Cloud | J1: Frameworks | K1: Models named | L1: Databases | M1: Infrastructure | N1: Compensation (if listed) | O1: Interview process (if public) | P1: Link | Q1: Date saved

Sheet Target Companies
A1: Company | B1: Type | C1: City | D1: Why this company | E1: AI work they do | F1: Contacts | G1: Open roles | H1: Priority | I1: Status | J1: Notes

Sheet Applications
A1: Role | B1: Company | C1: Date applied | D1: Source | E1: Job link | F1: Referral | G1: Stage | H1: Contact | I1: Next action | J1: Follow-up date | K1: Outcome / feedback | L1: Notes

Sheet Networking
A1: Name | B1: Company | C1: Role | D1: How we met | E1: Last contact | F1: Next step | G1: Next step date | H1: Referral status | I1: Notes

Sheet Weekly Review
A1: Week | B1: Week starting | C1: Shipped (links) | D1: Learned (3 concepts) | E1: Evidence added | F1: Blocked by / plan | G1: Hours actual | H1: Hours planned | I1: Energy (1-5) | J1: Next week: learn | K1: Next week: build | L1: Next week: publish
A2: 1 | B2: =IF(Dashboard!$C$7="","",Dashboard!$C$7+0) | H2: =Dashboard!$C$8
A3: 2 | B3: =IF(Dashboard!$C$7="","",Dashboard!$C$7+7) | H3: =Dashboard!$C$8
A4: 3 | B4: =IF(Dashboard!$C$7="","",Dashboard!$C$7+14) | H4: =Dashboard!$C$8
A5: 4 | B5: =IF(Dashboard!$C$7="","",Dashboard!$C$7+21) | H5: =Dashboard!$C$8
A6: 5 | B6: =IF(Dashboard!$C$7="","",Dashboard!$C$7+28) | H6: =Dashboard!$C$8
A7: 6 | B7: =IF(Dashboard!$C$7="","",Dashboard!$C$7+35) | H7: =Dashboard!$C$8
A8: 7 | B8: =IF(Dashboard!$C$7="","",Dashboard!$C$7+42) | H8: =Dashboard!$C$8
A9: 8 | B9: =IF(Dashboard!$C$7="","",Dashboard!$C$7+49) | H9: =Dashboard!$C$8
A10: 9 | B10: =IF(Dashboard!$C$7="","",Dashboard!$C$7+56) | H10: =Dashboard!$C$8
A11: 10 | B11: =IF(Dashboard!$C$7="","",Dashboard!$C$7+63) | H11: =Dashboard!$C$8
A12: 11 | B12: =IF(Dashboard!$C$7="","",Dashboard!$C$7+70) | H12: =Dashboard!$C$8
A13: 12 | B13: =IF(Dashboard!$C$7="","",Dashboard!$C$7+77) | H13: =Dashboard!$C$8
A14: 13 | B14: =IF(Dashboard!$C$7="","",Dashboard!$C$7+84) | H14: =Dashboard!$C$8
A15: 14 | B15: =IF(Dashboard!$C$7="","",Dashboard!$C$7+91) | H15: =Dashboard!$C$8
A16: 15 | B16: =IF(Dashboard!$C$7="","",Dashboard!$C$7+98) | H16: =Dashboard!$C$8
A17: 16 | B17: =IF(Dashboard!$C$7="","",Dashboard!$C$7+105) | H17: =Dashboard!$C$8
A18: 17 | B18: =IF(Dashboard!$C$7="","",Dashboard!$C$7+112) | H18: =Dashboard!$C$8
A19: 18 | B19: =IF(Dashboard!$C$7="","",Dashboard!$C$7+119) | H19: =Dashboard!$C$8
A20: 19 | B20: =IF(Dashboard!$C$7="","",Dashboard!$C$7+126) | H20: =Dashboard!$C$8
A21: 20 | B21: =IF(Dashboard!$C$7="","",Dashboard!$C$7+133) | H21: =Dashboard!$C$8
A22: 21 | B22: =IF(Dashboard!$C$7="","",Dashboard!$C$7+140) | H22: =Dashboard!$C$8
A23: 22 | B23: =IF(Dashboard!$C$7="","",Dashboard!$C$7+147) | H23: =Dashboard!$C$8
A24: 23 | B24: =IF(Dashboard!$C$7="","",Dashboard!$C$7+154) | H24: =Dashboard!$C$8
A25: 24 | B25: =IF(Dashboard!$C$7="","",Dashboard!$C$7+161) | H25: =Dashboard!$C$8
A26: 25 | B26: =IF(Dashboard!$C$7="","",Dashboard!$C$7+168) | H26: =Dashboard!$C$8
A27: 26 | B27: =IF(Dashboard!$C$7="","",Dashboard!$C$7+175) | H27: =Dashboard!$C$8
A28: 27 | B28: =IF(Dashboard!$C$7="","",Dashboard!$C$7+182) | H28: =Dashboard!$C$8
A29: 28 | B29: =IF(Dashboard!$C$7="","",Dashboard!$C$7+189) | H29: =Dashboard!$C$8
A30: 29 | B30: =IF(Dashboard!$C$7="","",Dashboard!$C$7+196) | H30: =Dashboard!$C$8
A31: 30 | B31: =IF(Dashboard!$C$7="","",Dashboard!$C$7+203) | H31: =Dashboard!$C$8
A32: 31 | B32: =IF(Dashboard!$C$7="","",Dashboard!$C$7+210) | H32: =Dashboard!$C$8
A33: 32 | B33: =IF(Dashboard!$C$7="","",Dashboard!$C$7+217) | H33: =Dashboard!$C$8
A34: 33 | B34: =IF(Dashboard!$C$7="","",Dashboard!$C$7+224) | H34: =Dashboard!$C$8
A35: 34 | B35: =IF(Dashboard!$C$7="","",Dashboard!$C$7+231) | H35: =Dashboard!$C$8
A36: 35 | B36: =IF(Dashboard!$C$7="","",Dashboard!$C$7+238) | H36: =Dashboard!$C$8
A37: 36 | B37: =IF(Dashboard!$C$7="","",Dashboard!$C$7+245) | H37: =Dashboard!$C$8
A38: 37 | B38: =IF(Dashboard!$C$7="","",Dashboard!$C$7+252) | H38: =Dashboard!$C$8
A39: 38 | B39: =IF(Dashboard!$C$7="","",Dashboard!$C$7+259) | H39: =Dashboard!$C$8
A40: 39 | B40: =IF(Dashboard!$C$7="","",Dashboard!$C$7+266) | H40: =Dashboard!$C$8
...

Sheet Monthly Review
A1: Month | B1: Theme | C1: Build | D1: Understand | E1: Evaluate | F1: Ship | G1: Communicate | H1: Interview | I1: Average | J1: Skills moved (with evidence) | K1: Project status | L1: Job research insights | M1: Questions I struggled with | N1: Decision | O1: One thing to stop doing
A2: 0 | B2: On-ramp: from zero to writing Python | I2: =IFERROR(ROUND(AVERAGE(C2:H2),2),"")
A3: 1 | B3: Engineering foundations and your first AI app | I3: =IFERROR(ROUND(AVERAGE(C3:H3),2),"")
A4: 2 | B4: LLM engineering core | I4: =IFERROR(ROUND(AVERAGE(C4:H4),2),"")
A5: 3 | B5: How LLMs actually work | I5: =IFERROR(ROUND(AVERAGE(C5:H5),2),"")
A6: 4 | B6: Retrieval-augmented generation | I6: =IFERROR(ROUND(AVERAGE(C6:H6),2),"")
A7: 5 | B7: Agents, tools and MCP | I7: =IFERROR(ROUND(AVERAGE(C7:H7),2),"")
A8: 6 | B8: Evaluation as an engineering system | I8: =IFERROR(ROUND(AVERAGE(C8:H8),2),"")
A9: 7 | B9: Production hardening and AI security | I9: =IFERROR(ROUND(AVERAGE(C9:H9),2),"")
A10: 8 | B10: Multimodal AI and fine-tuning | I10: =IFERROR(ROUND(AVERAGE(C10:H10),2),"")
A11: 9 | B11: AI infrastructure, advanced retrieval and capstone design | I11: =IFERROR(ROUND(AVERAGE(C11:H11),2),"")
A12: 10 | B12: Capstone build | I12: =IFERROR(ROUND(AVERAGE(C12:H12),2),"")
